Workbook

Sheet Todos
A1: CONTROLN | B1: STATE | C1: GENDER | D1: HV1 | E1: IC1 | F1: IC4 | G1: HVP1 | H1: IC5 | I1: POBC1 | J1: POBC2 | K1: IC2 | L1: IC3 | M1: AVGGIFT | N1: TCODE | O1: STATE | P1: DOB | Q1: DOMAIN | R1: GENDER | S1: TARGET_D | T1: AGE | U1: Neighbourhood
A2: 44060 | B2: FL | C2: M | D2: AAA896 | E2: 392 | F2: 520 | G2: 7 | H2: 21975 | I2: 6 | J2: 16 | K2: 430 | L2: 466 | M2: 28 | N2: =VLOOKUP(A2,vlookup_table!$A:$G,2,FALSE) -> 1 | O2: =VLOOKUP(A2,vlookup_table!$A:$G,3,FALSE) -> FL | P2: =VLOOKUP(A2,vlookup_table!$A:$G,4,FALSE) -> 1901 | Q2: =VLOOKUP(A2,vlookup_table!$A:$G,5,FALSE) -> C2 | R2: =VLOOKUP(A2,vlookup_table!$A:$G,6,FALSE) -> M | S2: =VLOOKUP(A2,vlookup_table!$A:$G,7,FALSE) -> 100 | T2: =97-LEFT(P2,2)-IF(RIGHT(P2,2)>6,1,0) -> 77 | U2: =IF(LEFT(Q2,1)="C","Ciudad",IF(LEFT(Q2,1)="T","Pueblo",IF(LEFT(Q2,1)="R","Rural",IF(LEFT(Q2,1)="S","Suburbano",IF(LEFT(Q2,1)="U","Urbano",""))))) -> Ciudad
A3: 96093 | B3: IL | C3: M | D3: 537 | E3: 365 | F3: 473 | G3: 0 | H3: 19387 | I3: 1 | J3: 89 | K3: 415 | L3: 410 | M3: 5.6666667 | N3: =VLOOKUP(A3,vlookup_table!$A:$G,2,FALSE) -> 0 | O3: =VLOOKUP(A3,vlookup_table!$A:$G,3,FALSE) -> IL | P3: =VLOOKUP(A3,vlookup_table!$A:$G,4,FALSE) -> 0 | Q3: =VLOOKUP(A3,vlookup_table!$A:$G,5,FALSE) -> T2 | R3: =VLOOKUP(A3,vlookup_table!$A:$G,6,FALSE) -> M | S3: =VLOOKUP(A3,vlookup_table!$A:$G,7,FALSE) -> 7 | T3: =97-LEFT(P3,2)-IF(RIGHT(P3,2)>6,1,0) -> 96 | U3: =IF(LEFT(Q3,1)="C","Ciudad",IF(LEFT(Q3,1)="T","Pueblo",IF(LEFT(Q3,1)="R","Rural",IF(LEFT(Q3,1)="S","Suburbano",IF(LEFT(Q3,1)="U","Urbano",""))))) -> Pueblo
A4: 43333 | B4: FL | C4: F | D4: 725 | E4: 301 | F4: 436 | G4: 3 | H4: 18837 | I4: 11 | J4: 17 | K4: 340 | L4: 361 | M4: 4.1111111 | N4: =VLOOKUP(A4,vlookup_table!$A:$G,2,FALSE) -> 0 | O4: =VLOOKUP(A4,vlookup_table!$A:$G,3,FALSE) -> FL | P4: =VLOOKUP(A4,vlookup_table!$A:$G,4,FALSE) -> 2501 | Q4: =VLOOKUP(A4,vlookup_table!$A:$G,5,FALSE) -> C2 | R4: =VLOOKUP(A4,vlookup_table!$A:$G,6,FALSE) -> F | S4: =VLOOKUP(A4,vlookup_table!$A:$G,7,FALSE) -> 5 | T4: =97-LEFT(P4,2)-IF(RIGHT(P4,2)>6,1,0) -> 71 | U4: =IF(LEFT(Q4,1)="C","Ciudad",IF(LEFT(Q4,1)="T","Pueblo",IF(LEFT(Q4,1)="R","Rural",IF(LEFT(Q4,1)="S","Suburbano",IF(LEFT(Q4,1)="U","Urbano",""))))) -> Ciudad
A5: 21885 | B5: NC | C5: M | D5: AAA1095 | E5: 401 | F5: 413 | G5: 7 | H5: 14014 | I5: 1 | J5: 74 | K5: 407 | L5: 399 | M5: 27.277778 | N5: =VLOOKUP(A5,vlookup_table!$A:$G,2,FALSE) -> 0 | O5: =VLOOKUP(A5,vlookup_table!$A:$G,3,FALSE) -> NC | P5: =VLOOKUP(A5,vlookup_table!$A:$G,4,FALSE) -> 2208 | Q5: =VLOOKUP(A5,vlookup_table!$A:$G,5,FALSE) -> T2 | R5: =VLOOKUP(A5,vlookup_table!$A:$G,6,FALSE) -> M | S5: =VLOOKUP(A5,vlookup_table!$A:$G,7,FALSE) -> 38 | T5: =97-LEFT(P5,2)-IF(RIGHT(P5,2)>6,1,0) -> 74 | U5: =IF(LEFT(Q5,1)="C","Ciudad",IF(LEFT(Q5,1)="T","Pueblo",IF(LEFT(Q5,1)="R","Rural",IF(LEFT(Q5,1)="S","Suburbano",IF(LEFT(Q5,1)="U","Urbano",""))))) -> Pueblo
A6: 190108 | B6: FL | C6: F | D6: 995 | E6: 252 | F6: 348 | G6: 0 | H6: 17991 | I6: 5 | J6: 6 | K6: 280 | L6: 316 | M6: 6 | N6: =VLOOKUP(A6,vlookup_table!$A:$G,2,FALSE) -> 28 | O6: =VLOOKUP(A6,vlookup_table!$A:$G,3,FALSE) -> FL | P6: =VLOOKUP(A6,vlookup_table!$A:$G,4,FALSE) -> 0 | Q6: =VLOOKUP(A6,vlookup_table!$A:$G,5,FALSE) -> C2 | R6: =VLOOKUP(A6,vlookup_table!$A:$G,6,FALSE) -> F | S6: =VLOOKUP(A6,vlookup_table!$A:$G,7,FALSE) -> 5 | T6: =97-LEFT(P6,2)-IF(RIGHT(P6,2)>6,1,0) -> 96 | U6: =IF(LEFT(Q6,1)="C","Ciudad",IF(LEFT(Q6,1)="T","Pueblo",IF(LEFT(Q6,1)="R","Rural",IF(LEFT(Q6,1)="S","Suburbano",IF(LEFT(Q6,1)="U","Urbano",""))))) -> Ciudad
A7: 100640 | B7: IL | C7: M | D7: 764 | E7: 457 | F7: 501 | G7: 1 | H7: 16022 | I7: 2 | J7: 75 | K7: 477 | L7: 480 | M7: 25.571429 | N7: =VLOOKUP(A7,vlookup_table!$A:$G,2,FALSE) -> 1 | O7: =VLOOKUP(A7,vlookup_table!$A:$G,3,FALSE) -> IL | P7: =VLOOKUP(A7,vlookup_table!$A:$G,4,FALSE) -> 6104 | Q7: =VLOOKUP(A7,vlookup_table!$A:$G,5,FALSE) -> S2 | R7: =VLOOKUP(A7,vlookup_table!$A:$G,6,FALSE) -> M | S7: =VLOOKUP(A7,vlookup_table!$A:$G,7,FALSE) -> 30 | T7: =97-LEFT(P7,2)-IF(RIGHT(P7,2)>6,1,0) -> 35 | U7: =IF(LEFT(Q7,1)="C","Ciudad",IF(LEFT(Q7,1)="T","Pueblo",IF(LEFT(Q7,1)="R","Rural",IF(LEFT(Q7,1)="S","Suburbano",IF(LEFT(Q7,1)="U","Urbano",""))))) -> Suburbano
A8: 18581 | B8: NC | C8: F | D8: 775 | E8: 318 | F8: 419 | G8: 5 | H8: 13491 | I8: 0 | J8: 73 | K8: 364 | L8: 380 | M8: 4.625 | N8: =VLOOKUP(A8,vlookup_table!$A:$G,2,FALSE) -> 0 | O8: =VLOOKUP(A8,vlookup_table!$A:$G,3,FALSE) -> NC | P8: =VLOOKUP(A8,vlookup_table!$A:$G,4,FALSE) -> 4407 | Q8: =VLOOKUP(A8,vlookup_table!$A:$G,5,FALSE) -> R2 | R8: =VLOOKUP(A8,vlookup_table!$A:$G,6,FALSE) -> F | S8: =VLOOKUP(A8,vlookup_table!$A:$G,7,FALSE) -> 12 | T8: =97-LEFT(P8,2)-IF(RIGHT(P8,2)>6,1,0) -> 52 | U8: =IF(LEFT(Q8,1)="C","Ciudad",IF(LEFT(Q8,1)="T","Pueblo",IF(LEFT(Q8,1)="R","Rural",IF(LEFT(Q8,1)="S","Suburbano",IF(LEFT(Q8,1)="U","Urbano",""))))) -> Rural
A9: 119038 | B9: TX | C9: M | D9: 890 | E9: 519 | F9: 560 | G9: 0 | H9: 17872 | I9: 2 | J9: 46 | K9: 525 | L9: 551 | M9: 6.175 | N9: =VLOOKUP(A9,vlookup_table!$A:$G,2,FALSE) -> 1002 | O9: =VLOOKUP(A9,vlookup_table!$A:$G,3,FALSE) -> TX | P9: =VLOOKUP(A9,vlookup_table!$A:$G,4,FALSE) -> 0 | Q9: =VLOOKUP(A9,vlookup_table!$A:$G,5,FALSE) -> C1 | R9: =VLOOKUP(A9,vlookup_table!$A:$G,6,FALSE) -> M | S9: =VLOOKUP(A9,vlookup_table!$A:$G,7,FALSE) -> 7 | T9: =97-LEFT(P9,2)-IF(RIGHT(P9,2)>6,1,0) -> 96 | U9: =IF(LEFT(Q9,1)="C","Ciudad",IF(LEFT(Q9,1)="T","Pueblo",IF(LEFT(Q9,1)="R","Rural",IF(LEFT(Q9,1)="S","Suburbano",IF(LEFT(Q9,1)="U","Urbano",""))))) -> Ciudad
A10: 173223 | B10: CA | C10: F | E10: 184 | F10: 250 | G10: 0 | H10: 8708 | I10: 2 | J10: 63 | K10: 206 | L10: 235 | M10: 8.8181818 | N10: =VLOOKUP(A10,vlookup_table!$A:$G,2,FALSE) -> 0 | O10: =VLOOKUP(A10,vlookup_table!$A:$G,3,FALSE) -> CA | P10: =VLOOKUP(A10,vlookup_table!$A:$G,4,FALSE) -> 1801 | Q10: =VLOOKUP(A10,vlookup_table!$A:$G,5,FALSE) -> T2 | R10: =VLOOKUP(A10,vlookup_table!$A:$G,6,FALSE) -> F | S10: =VLOOKUP(A10,vlookup_table!$A:$G,7,FALSE) -> 10 | T10: =97-LEFT(P10,2)-IF(RIGHT(P10,2)>6,1,0) -> 78 | U10: =IF(LEFT(Q10,1)="C","Ciudad",IF(LEFT(Q10,1)="T","Pueblo",IF(LEFT(Q10,1)="R","Rural",IF(LEFT(Q10,1)="S","Suburbano",IF(LEFT(Q10,1)="U","Urbano",""))))) -> Pueblo
A11: 157988 | B11: CA | C11: F | D11: AAA2294 | E11: 593 | F11: 617 | G11: 61 | H11: 17838 | I11: 7 | J11: 62 | L11: 619 | M11: 6.6666667 | N11: =VLOOKUP(A11,vlookup_table!$A:$G,2,FALSE) -> 28 | O11: =VLOOKUP(A11,vlookup_table!$A:$G,3,FALSE) -> CA | P11: =VLOOKUP(A11,vlookup_table!$A:$G,4,FALSE) -> 0 | Q11: =VLOOKUP(A11,vlookup_table!$A:$G,5,FALSE) -> S1 | R11: =VLOOKUP(A11,vlookup_table!$A:$G,6,FALSE) -> F | S11: =VLOOKUP(A11,vlookup_table!$A:$G,7,FALSE) -> 10 | T11: =97-LEFT(P11,2)-IF(RIGHT(P11,2)>6,1,0) -> 96 | U11: =IF(LEFT(Q11,1)="C","Ciudad",IF(LEFT(Q11,1)="T","Pueblo",IF(LEFT(Q11,1)="R","Rural",IF(LEFT(Q11,1)="S","Suburbano",IF(LEFT(Q11,1)="U","Urbano",""))))) -> Suburbano
A12: 141720 | B12: NV | C12: F | D12: 1569 | E12: 673 | F12: 781 | G12: 22 | H12: 25775 | I12: 3 | J12: 44 | K12: 672 | L12: 785 | M12: 13 | N12: =VLOOKUP(A12,vlookup_table!$A:$G,2,FALSE) -> 28 | O12: =VLOOKUP(A12,vlookup_table!$A:$G,3,FALSE) -> NV | P12: =VLOOKUP(A12,vlookup_table!$A:$G,4,FALSE) -> 5401 | Q12: =VLOOKUP(A12,vlookup_table!$A:$G,5,FALSE) -> T1 | R12: =VLOOKUP(A12,vlookup_table!$A:$G,6,FALSE) -> F | S12: =VLOOKUP(A12,vlookup_table!$A:$G,7,FALSE) -> 5 | T12: =97-LEFT(P12,2)-IF(RIGHT(P12,2)>6,1,0) -> 42 | U12: =IF(LEFT(Q12,1)="C","Ciudad",IF(LEFT(Q12,1)="T","Pueblo",IF(LEFT(Q12,1)="R","Rural",IF(LEFT(Q12,1)="S","Suburbano",IF(LEFT(Q12,1)="U","Urbano",""))))) -> Pueblo
A13: 186272 | B13: CA | C13: F | D13: 3515 | E13: 521 | F13: 588 | G13: 97 | H13: 20068 | I13: 11 | J13: 54 | K13: 565 | L13: 549 | M13: 8.64 | N13: =VLOOKUP(A13,vlookup_table!$A:$G,2,FALSE) -> 2 | O13: =VLOOKUP(A13,vlookup_table!$A:$G,3,FALSE) -> CA | P13: =VLOOKUP(A13,vlookup_table!$A:$G,4,FALSE) -> 3401 | Q13: =VLOOKUP(A13,vlookup_table!$A:$G,5,FALSE) -> U1 | R13: =VLOOKUP(A13,vlookup_table!$A:$G,6,FALSE) -> F | S13: =VLOOKUP(A13,vlookup_table!$A:$G,7,FALSE) -> 10 | T13: =97-LEFT(P13,2)-IF(RIGHT(P13,2)>6,1,0) -> 62 | U13: =IF(LEFT(Q13,1)="C","Ciudad",IF(LEFT(Q13,1)="T","Pueblo",IF(LEFT(Q13,1)="R","Rural",IF(LEFT(Q13,1)="S","Suburbano",IF(LEFT(Q13,1)="U","Urbano",""))))) -> Urbano
A14: 154301 | B14: CL | C14: F | D14: 1026 | E14: 459 | F14: 496 | G14: 1 | H14: 13803 | I14: 12 | J14: 52 | K14: 470 | L14: 491 | M14: 11.25 | N14: =VLOOKUP(A14,vlookup_table!$A:$G,2,FALSE) -> 2 | O14: =VLOOKUP(A14,vlookup_table!$A:$G,3,FALSE) -> CA | P14: =VLOOKUP(A14,vlookup_table!$A:$G,4,FALSE) -> 2801 | Q14: =VLOOKUP(A14,vlookup_table!$A:$G,5,FALSE) -> T2 | R14: =VLOOKUP(A14,vlookup_table!$A:$G,6,FALSE) -> F | S14: =VLOOKUP(A14,vlookup_table!$A:$G,7,FALSE) -> 10 | T14: =97-LEFT(P14,2)-IF(RIGHT(P14,2)>6,1,0) -> 68 | U14: =IF(LEFT(Q14,1)="C","Ciudad",IF(LEFT(Q14,1)="T","Pueblo",IF(LEFT(Q14,1)="R","Rural",IF(LEFT(Q14,1)="S","Suburbano",IF(LEFT(Q14,1)="U","Urbano",""))))) -> Pueblo
A15: 189722 | B15: AP | C15: M | D15: 0 | E15: 0 | F15: 0 | G15: 0 | H15: 0 | I15: 0 | J15: 0 | K15: 0 | L15: 0 | M15: 5.7272727 | N15: =VLOOKUP(A15,vlookup_table!$A:$G,2,FALSE) -> 1 | O15: =VLOOKUP(A15,vlookup_table!$A:$G,3,FALSE) -> AP | P15: =VLOOKUP(A15,vlookup_table!$A:$G,4,FALSE) -> 0 | Q15: =VLOOKUP(A15,vlookup_table!$A:$G,5,FALSE) | R15: =VLOOKUP(A15,vlookup_table!$A:$G,6,FALSE) -> M | S15: =VLOOKUP(A15,vlookup_table!$A:$G,7,FALSE) -> 6 | T15: =97-LEFT(P15,2)-IF(RIGHT(P15,2)>6,1,0) -> 96 | U15: =IF(LEFT(Q15,1)="C","Ciudad",IF(LEFT(Q15,1)="T","Pueblo",IF(LEFT(Q15,1)="R","Rural",IF(LEFT(Q15,1)="S","Suburbano",IF(LEFT(Q15,1)="U","Urbano","")))))
A16: 188304 | B16: KS | C16: F | D16: 376 | E16: 263 | F16: 316 | G16: 0 | H16: 10755 | I16: 1 | J16: 75 | K16: 303 | L16: 287 | M16: 10.55 | N16: =VLOOKUP(A16,vlookup_table!$A:$G,2,FALSE) -> 0 | O16: =VLOOKUP(A16,vlookup_table!$A:$G,3,FALSE) -> KS | P16: =VLOOKUP(A16,vlookup_table!$A:$G,4,FALSE) -> 2405 | Q16: =VLOOKUP(A16,vlookup_table!$A:$G,5,FALSE) -> T2 | R16: =VLOOKUP(A16,vlookup_table!$A:$G,6,FALSE) -> F | S16: =VLOOKUP(A16,vlookup_table!$A:$G,7,FALSE) -> 10 | T16: =97-LEFT(P16,2)-IF(RIGHT(P16,2)>6,1,0) -> 72 | U16: =IF(LEFT(Q16,1)="C","Ciudad",IF(LEFT(Q16,1)="T","Pueblo",IF(LEFT(Q16,1)="R","Rural",IF(LEFT(Q16,1)="S","Suburbano",IF(LEFT(Q16,1)="U","Urbano",""))))) -> Pueblo
A17: 73699 | B17: MI | D17: 890 | E17: 463 | F17: 523 | G17: 1 | H17: 9493 | I17: 5 | J17: 53 | K17: 474 | L17: 512 | M17: 11.285714 | N17: =VLOOKUP(A17,vlookup_table!$A:$G,2,FALSE) -> 1 | O17: =VLOOKUP(A17,vlookup_table!$A:$G,3,FALSE) -> MI | P17: =VLOOKUP(A17,vlookup_table!$A:$G,4,FALSE) -> 5102 | Q17: =VLOOKUP(A17,vlookup_table!$A:$G,5,FALSE) -> S1 | R17: =VLOOKUP(A17,vlookup_table!$A:$G,6,FALSE) | S17: =VLOOKUP(A17,vlookup_table!$A:$G,7,FALSE) -> 15 | T17: =97-LEFT(P17,2)-IF(RIGHT(P17,2)>6,1,0) -> 45 | U17: =IF(LEFT(Q17,1)="C","Ciudad",IF(LEFT(Q17,1)="T","Pueblo",IF(LEFT(Q17,1)="R","Rural",IF(LEFT(Q17,1)="S","Suburbano",IF(LEFT(Q17,1)="U","Urbano",""))))) -> Suburbano
A18: 31977 | B18: FL | C18: F | D18: 1513 | E18: 521 | F18: 702 | G18: 31 | H18: 28124 | I18: 3 | J18: 24 | K18: 599 | L18: 615 | M18: 18.5 | N18: =VLOOKUP(A18,vlookup_table!$A:$G,2,FALSE) -> 2 | O18: =VLOOKUP(A18,vlookup_table!$A:$G,3,FALSE) -> FL | P18: =VLOOKUP(A18,vlookup_table!$A:$G,4,FALSE) -> 2701 | Q18: =VLOOKUP(A18,vlookup_table!$A:$G,5,FALSE) -> T1 | R18: =VLOOKUP(A18,vlookup_table!$A:$G,6,FALSE) -> F | S18: =VLOOKUP(A18,vlookup_table!$A:$G,7,FALSE) -> 28 | T18: =97-LEFT(P18,2)-IF(RIGHT(P18,2)>6,1,0) -> 69 | U18: =IF(LEFT(Q18,1)="C","Ciudad",IF(LEFT(Q18,1)="T","Pueblo",IF(LEFT(Q18,1)="R","Rural",IF(LEFT(Q18,1)="S","Suburbano",IF(LEFT(Q18,1)="U","Urbano",""))))) -> Pueblo
A19: 44336 | B19: FL | C19: F | D19: 948 | E19: 330 | F19: 411 | G19: 4 | H19: 17728 | I19: 6 | J19: 8 | K19: 365 | L19: 368 | M19: 15 | N19: =VLOOKUP(A19,vlookup_table!$A:$G,2,FALSE) -> 0 | O19: =VLOOKUP(A19,vlookup_table!$A:$G,3,FALSE) -> FL | P19: =VLOOKUP(A19,vlookup_table!$A:$G,4,FALSE) -> 6501 | Q19: =VLOOKUP(A19,vlookup_table!$A:$G,5,FALSE) -> C2 | R19: =VLOOKUP(A19,vlookup_table!$A:$G,6,FALSE) -> F | S19: =VLOOKUP(A19,vlookup_table!$A:$G,7,FALSE) -> 15 | T19: =97-LEFT(P19,2)-IF(RIGHT(P19,2)>6,1,0) -> 31 | U19: =IF(LEFT(Q19,1)="C","Ciudad",IF(LEFT(Q19,1)="T","Pueblo",IF(LEFT(Q19,1)="R","Rural",IF(LEFT(Q19,1)="S","Suburbano",IF(LEFT(Q19,1)="U","Urbano",""))))) -> Ciudad
A20: 127823 | B20: TX | C20: F | D20: 258 | E20: 64 | F20: 74 | G20: 0 | H20: 4236 | I20: 0 | J20: 94 | K20: 60 | L20: 93 | M20: 5.45 | N20: =VLOOKUP(A20,vlookup_table!$A:$G,2,FALSE) -> 2 | O20: =VLOOKUP(A20,vlookup_table!$A:$G,3,FALSE) -> TX | P20: =VLOOKUP(A20,vlookup_table!$A:$G,4,FALSE) -> 2301 | Q20: =VLOOKUP(A20,vlookup_table!$A:$G,5,FALSE) -> C3 | R20: =VLOOKUP(A20,vlookup_table!$A:$G,6,FALSE) -> F | S20: =VLOOKUP(A20,vlookup_table!$A:$G,7,FALSE) -> 6 | T20: =97-LEFT(P20,2)-IF(RIGHT(P20,2)>6,1,0) -> 73 | U20: =IF(LEFT(Q20,1)="C","Ciudad",IF(LEFT(Q20,1)="T","Pueblo",IF(LEFT(Q20,1)="R","Rural",IF(LEFT(Q20,1)="S","Suburbano",IF(LEFT(Q20,1)="U","Urbano",""))))) -> Ciudad
A21: 150739 | B21: CA | C21: U | D21: 1951 | E21: 556 | F21: 625 | G21: 44 | H21: 17208 | I21: 10 | J21: 66 | K21: 578 | L21: 619 | M21: 9.6818182 | N21: =VLOOKUP(A21,vlookup_table!$A:$G,2,FALSE) -> 2 | O21: =VLOOKUP(A21,vlookup_table!$A:$G,3,FALSE) -> CA | P21: =VLOOKUP(A21,vlookup_table!$A:$G,4,FALSE) -> 5410 | Q21: =VLOOKUP(A21,vlookup_table!$A:$G,5,FALSE) -> S1 | R21: =VLOOKUP(A21,vlookup_table!$A:$G,6,FALSE) -> U | S21: =VLOOKUP(A21,vlookup_table!$A:$G,7,FALSE) -> 12 | T21: =97-LEFT(P21,2)-IF(RIGHT(P21,2)>6,1,0) -> 42 | U21: =IF(LEFT(Q21,1)="C","Ciudad",IF(LEFT(Q21,1)="T","Pueblo",IF(LEFT(Q21,1)="R","Rural",IF(LEFT(Q21,1)="S","Suburbano",IF(LEFT(Q21,1)="U","Urbano",""))))) -> Suburbano
A22: 41384 | B22: FL | C22: F | D22: 556 | E22: 318 | G22: 0 | H22: 11779 | I22: 16 | J22: 22 | K22: 358 | L22: 320 | M22: 9.4285714 | N22: =VLOOKUP(A22,vlookup_table!$A:$G,2,FALSE) -> 28 | O22: =VLOOKUP(A22,vlookup_table!$A:$G,3,FALSE) -> FL | P22: =VLOOKUP(A22,vlookup_table!$A:$G,4,FALSE) -> 5107 | Q22: =VLOOKUP(A22,vlookup_table!$A:$G,5,FALSE) -> S3 | R22: =VLOOKUP(A22,vlookup_table!$A:$G,6,FALSE) -> F | S22: =VLOOKUP(A22,vlookup_table!$A:$G,7,FALSE) -> 12 | T22: =97-LEFT(P22,2)-IF(RIGHT(P22,2)>6,1,0) -> 45 | U22: =IF(LEFT(Q22,1)="C","Ciudad",IF(LEFT(Q22,1)="T","Pueblo",IF(LEFT(Q22,1)="R","Rural",IF(LEFT(Q22,1)="S","Suburbano",IF(LEFT(Q22,1)="U","Urbano",""))))) -> Suburbano
A23: 114721 | B23: OK | D23: 1040 | E23: 472 | F23: 656 | G23: 0 | H23: 26962 | I23: 2 | J23: 56 | K23: 609 | L23: 579 | M23: 11.666667 | N23: =VLOOKUP(A23,vlookup_table!$A:$G,2,FALSE) -> 0 | O23: =VLOOKUP(A23,vlookup_table!$A:$G,3,FALSE) -> OK | P23: =VLOOKUP(A23,vlookup_table!$A:$G,4,FALSE) -> 0 | Q23: =VLOOKUP(A23,vlookup_table!$A:$G,5,FALSE) -> C2 | R23: =VLOOKUP(A23,vlookup_table!$A:$G,6,FALSE) | S23: =VLOOKUP(A23,vlookup_table!$A:$G,7,FALSE) -> 15 | T23: =97-LEFT(P23,2)-IF(RIGHT(P23,2)>6,1,0) -> 96 | U23: =IF(LEFT(Q23,1)="C","Ciudad",IF(LEFT(Q23,1)="T","Pueblo",IF(LEFT(Q23,1)="R","Rural",IF(LEFT(Q23,1)="S","Suburbano",IF(LEFT(Q23,1)="U","Urbano",""))))) -> Ciudad
A24: 111795 | B24: AR | D24: 603 | E24: 208 | F24: 341 | G24: 2 | H24: 12038 | I24: 1 | J24: 70 | K24: 264 | L24: 288 | M24: 5 | N24: =VLOOKUP(A24,vlookup_table!$A:$G,2,FALSE) -> 0 | O24: =VLOOKUP(A24,vlookup_table!$A:$G,3,FALSE) -> AR | P24: =VLOOKUP(A24,vlookup_table!$A:$G,4,FALSE) -> 0 | Q24: =VLOOKUP(A24,vlookup_table!$A:$G,5,FALSE) | R24: =VLOOKUP(A24,vlookup_table!$A:$G,6,FALSE) | S24: =VLOOKUP(A24,vlookup_table!$A:$G,7,FALSE) -> 5 | T24: =97-LEFT(P24,2)-IF(RIGHT(P24,2)>6,1,0) -> 96 | U24: =IF(LEFT(Q24,1)="C","Ciudad",IF(LEFT(Q24,1)="T","Pueblo",IF(LEFT(Q24,1)="R","Rural",IF(LEFT(Q24,1)="S","Suburbano",IF(LEFT(Q24,1)="U","Urbano","")))))
A25: 64480 | B25: IN | C25: F | D25: 526 | E25: 277 | F25: 370 | G25: 1 | H25: 12826 | I25: 1 | J25: 80 | K25: 336 | L25: 317 | M25: 7.1428571 | N25: =VLOOKUP(A25,vlookup_table!$A:$G,2,FALSE) -> 28 | O25: =VLOOKUP(A25,vlookup_table!$A:$G,3,FALSE) -> IN | P25: =VLOOKUP(A25,vlookup_table!$A:$G,4,FALSE) -> 0 | Q25: =VLOOKUP(A25,vlookup_table!$A:$G,5,FALSE) -> T2 | R25: =VLOOKUP(A25,vlookup_table!$A:$G,6,FALSE) -> F | S25: =VLOOKUP(A25,vlookup_table!$A:$G,7,FALSE) -> 10 | T25: =97-LEFT(P25,2)-IF(RIGHT(P25,2)>6,1,0) -> 96 | U25: =IF(LEFT(Q25,1)="C","Ciudad",IF(LEFT(Q25,1)="T","Pueblo",IF(LEFT(Q25,1)="R","Rural",IF(LEFT(Q25,1)="S","Suburbano",IF(LEFT(Q25,1)="U","Urbano",""))))) -> Pueblo
A26: 87259 | B26: MT | C26: M | D26: 717 | E26: 302 | F26: 432 | G26: 1 | H26: 15614 | I26: 1 | J26: 53 | K26: 458 | L26: 349 | M26: 9.7 | N26: =VLOOKUP(A26,vlookup_table!$A:$G,2,FALSE) -> 2 | O26: =VLOOKUP(A26,vlookup_table!$A:$G,3,FALSE) -> MT | P26: =VLOOKUP(A26,vlookup_table!$A:$G,4,FALSE) -> 4304 | Q26: =VLOOKUP(A26,vlookup_table!$A:$G,5,FALSE) -> C1 | R26: =VLOOKUP(A26,vlookup_table!$A:$G,6,FALSE) -> M | S26: =VLOOKUP(A26,vlookup_table!$A:$G,7,FALSE) -> 25 | T26: =97-LEFT(P26,2)-IF(RIGHT(P26,2)>6,1,0) -> 53 | U26: =IF(LEFT(Q26,1)="C","Ciudad",IF(LEFT(Q26,1)="T","Pueblo",IF(LEFT(Q26,1)="R","Rural",IF(LEFT(Q26,1)="S","Suburbano",IF(LEFT(Q26,1)="U","Urbano",""))))) -> Ciudad
A27: 115823 | B27: TX | C27: M | D27: 1011 | E27: 593 | F27: 650 | G27: 1 | H27: 17606 | I27: 5 | J27: 61 | K27: 588 | L27: 650 | M27: 6.5 | N27: =VLOOKUP(A27,vlookup_table!$A:$G,2,FALSE) -> 0 | O27: =VLOOKUP(A27,vlookup_table!$A:$G,3,FALSE) -> TX | P27: =VLOOKUP(A27,vlookup_table!$A:$G,4,FALSE) -> 0 | Q27: =VLOOKUP(A27,vlookup_table!$A:$G,5,FALSE) -> S1 | R27: =VLOOKUP(A27,vlookup_table!$A:$G,6,FALSE) -> M | S27: =VLOOKUP(A27,vlookup_table!$A:$G,7,FALSE) -> 15 | T27: =97-LEFT(P27,2)-IF(RIGHT(P27,2)>6,1,0) -> 96 | U27: =IF(LEFT(Q27,1)="C","Ciudad",IF(LEFT(Q27,1)="T","Pueblo",IF(LEFT(Q27,1)="R","Rural",IF(LEFT(Q27,1)="S","Suburbano",IF(LEFT(Q27,1)="U","Urbano",""))))) -> Suburbano
A28: 95701 | B28: IL | C28: M | D28: 1063 | E28: 255 | F28: 317 | G28: 3 | H28: 14023 | I28: 16 | J28: 53 | K28: 260 | L28: 312 | M28: 8.3727907 | N28: =VLOOKUP(A28,vlookup_table!$A:$G,2,FALSE) -> 1 | O28: =VLOOKUP(A28,vlookup_table!$A:$G,3,FALSE) -> IL | P28: =VLOOKUP(A28,vlookup_table!$A:$G,4,FALSE) -> 4406 | Q28: =VLOOKUP(A28,vlookup_table!$A:$G,5,FALSE) -> S2 | R28: =VLOOKUP(A28,vlookup_table!$A:$G,6,FALSE) -> M | S28: =VLOOKUP(A28,vlookup_table!$A:$G,7,FALSE) -> 5 | T28: =97-LEFT(P28,2)-IF(RIGHT(P28,2)>6,1,0) -> 52 | U28: =IF(LEFT(Q28,1)="C","Ciudad",IF(LEFT(Q28,1)="T","Pueblo",IF(LEFT(Q28,1)="R","Rural",IF(LEFT(Q28,1)="S","Suburbano",IF(LEFT(Q28,1)="U","Urbano",""))))) -> Suburbano
A29: 5172 | B29: IL | C29: M | D29: 291 | E29: 136 | F29: 212 | G29: 0 | H29: 8370 | I29: 5 | J29: 67 | K29: 168 | L29: 180 | M29: 10.611111 | N29: =VLOOKUP(A29,vlookup_table!$A:$G,2,FALSE) -> 1 | O29: =VLOOKUP(A29,vlookup_table!$A:$G,3,FALSE) -> IL | P29: =VLOOKUP(A29,vlookup_table!$A:$G,4,FALSE) -> 6105 | Q29: =VLOOKUP(A29,vlookup_table!$A:$G,5,FALSE) -> R3 | R29: =VLOOKUP(A29,vlookup_table!$A:$G,6,FALSE) -> M | S29: =VLOOKUP(A29,vlookup_table!$A:$G,7,FALSE) -> 10 | T29: =97-LEFT(P29,2)-IF(RIGHT(P29,2)>6,1,0) -> 35 | U29: =IF(LEFT(Q29,1)="C","Ciudad",IF(LEFT(Q29,1)="T","Pueblo",IF(LEFT(Q29,1)="R","Rural",IF(LEFT(Q29,1)="S","Suburbano",IF(LEFT(Q29,1)="U","Urbano",""))))) -> Rural
A30: 152486 | B30: CA | C30: M | D30: 1538 | E30: 271 | F30: 393 | G30: 11 | H30: 15627 | I30: 5 | J30: 49 | K30: 317 | L30: 342 | M30: 5.5 | N30: =VLOOKUP(A30,vlookup_table!$A:$G,2,FALSE) -> 1 | O30: =VLOOKUP(A30,vlookup_table!$A:$G,3,FALSE) -> CA | P30: =VLOOKUP(A30,vlookup_table!$A:$G,4,FALSE) -> 2401 | Q30: =VLOOKUP(A30,vlookup_table!$A:$G,5,FALSE) -> S2 | R30: =VLOOKUP(A30,vlookup_table!$A:$G,6,FALSE) -> M | S30: =VLOOKUP(A30,vlookup_table!$A:$G,7,FALSE) -> 5 | T30: =97-LEFT(P30,2)-IF(RIGHT(P30,2)>6,1,0) -> 72 | U30: =IF(LEFT(Q30,1)="C","Ciudad",IF(LEFT(Q30,1)="T","Pueblo",IF(LEFT(Q30,1)="R","Rural",IF(LEFT(Q30,1)="S","Suburbano",IF(LEFT(Q30,1)="U","Urbano",""))))) -> Suburbano
A31: 153880 | B31: WI | C31: F | D31: 592 | E31: 244 | F31: 392 | G31: 1 | H31: 12220 | I31: 3 | J31: 74 | K31: 341 | L31: 306 | M31: 12.5 | N31: =VLOOKUP(A31,vlookup_table!$A:$G,2,FALSE) -> 2 | O31: =VLOOKUP(A31,vlookup_table!$A:$G,3,FALSE) -> WI | P31: =VLOOKUP(A31,vlookup_table!$A:$G,4,FALSE) -> 5001 | Q31: =VLOOKUP(A31,vlookup_table!$A:$G,5,FALSE) -> S1 | R31: =VLOOKUP(A31,vlookup_table!$A:$G,6,FALSE) -> F | S31: =VLOOKUP(A31,vlookup_table!$A:$G,7,FALSE) -> 5 | T31: =97-LEFT(P31,2)-IF(RIGHT(P31,2)>6,1,0) -> 46 | U31: =IF(LEFT(Q31,1)="C","Ciudad",IF(LEFT(Q31,1)="T","Pueblo",IF(LEFT(Q31,1)="R","Rural",IF(LEFT(Q31,1)="S","Suburbano",IF(LEFT(Q31,1)="U","Urbano",""))))) -> Suburbano
A32: 101855 | B32: MO | C32: M | D32: 871 | E32: 340 | F32: 416 | G32: 6 | H32: 15336 | I32: 0 | J32: 71 | K32: 385 | L32: 365 | M32: 7.8571429 | N32: =VLOOKUP(A32,vlookup_table!$A:$G,2,FALSE) -> 1 | O32: =VLOOKUP(A32,vlookup_table!$A:$G,3,FALSE) -> MO | P32: =VLOOKUP(A32,vlookup_table!$A:$G,4,FALSE) -> 2401 | Q32: =VLOOKUP(A32,vlookup_table!$A:$G,5,FALSE) -> C2 | R32: =VLOOKUP(A32,vlookup_table!$A:$G,6,FALSE) -> M | S32: =VLOOKUP(A32,vlookup_table!$A:$G,7,FALSE) -> 10 | T32: =97-LEFT(P32,2)-IF(RIGHT(P32,2)>6,1,0) -> 72 | U32: =IF(LEFT(Q32,1)="C","Ciudad",IF(LEFT(Q32,1)="T","Pueblo",IF(LEFT(Q32,1)="R","Rural",IF(LEFT(Q32,1)="S","Suburbano",IF(LEFT(Q32,1)="U","Urbano",""))))) -> Ciudad
A33: 62932 | B33: IN | C33: M | D33: 403 | E33: 174 | F33: 264 | G33: 1 | H33: 9704 | I33: 0 | J33: 45 | K33: 240 | L33: 201 | M33: 8 | N33: =VLOOKUP(A33,vlookup_table!$A:$G,2,FALSE) -> 1 | O33: =VLOOKUP(A33,vlookup_table!$A:$G,3,FALSE) -> IN | P33: =VLOOKUP(A33,vlookup_table!$A:$G,4,FALSE) -> 0 | Q33: =VLOOKUP(A33,vlookup_table!$A:$G,5,FALSE) -> S3 | R33: =VLOOKUP(A33,vlookup_table!$A:$G,6,FALSE) -> M | S33: =VLOOKUP(A33,vlookup_table!$A:$G,7,FALSE) -> 10 | T33: =97-LEFT(P33,2)-IF(RIGHT(P33,2)>6,1,0) -> 96 | U33: =IF(LEFT(Q33,1)="C","Ciudad",IF(LEFT(Q33,1)="T","Pueblo",IF(LEFT(Q33,1)="R","Rural",IF(LEFT(Q33,1)="S","Suburbano",IF(LEFT(Q33,1)="U","Urbano",""))))) -> Suburbano
A34: 125930 | B34: TX | C34: F | D34: 715 | E34: 339 | F34: 396 | G34: 1 | H34: 12617 | I34: 3 | J34: 88 | K34: 378 | L34: 371 | M34: 6 | N34: =VLOOKUP(A34,vlookup_table!$A:$G,2,FALSE) -> 0 | O34: =VLOOKUP(A34,vlookup_table!$A:$G,3,FALSE) -> TX | P34: =VLOOKUP(A34,vlookup_table!$A:$G,4,FALSE) -> 4806 | Q34: =VLOOKUP(A34,vlookup_table!$A:$G,5,FALSE) -> R2 | R34: =VLOOKUP(A34,vlookup_table!$A:$G,6,FALSE) -> F | S34: =VLOOKUP(A34,vlookup_table!$A:$G,7,FALSE) -> 75 | T34: =97-LEFT(P34,2)-IF(RIGHT(P34,2)>6,1,0) -> 48 | U34: =IF(LEFT(Q34,1)="C","Ciudad",IF(LEFT(Q34,1)="T","Pueblo",IF(LEFT(Q34,1)="R","Rural",IF(LEFT(Q34,1)="S","Suburbano",IF(LEFT(Q34,1)="U","Urbano",""))))) -> Rural
A35: 173653 | B35: HI | C35: F | D35: 2346 | E35: 420 | F35: 503 | G35: 67 | H35: 14552 | I35: 5 | J35: 78 | K35: 446 | L35: 468 | M35: 15.5 | N35: =VLOOKUP(A35,vlookup_table!$A:$G,2,FALSE) -> 28 | O35: =VLOOKUP(A35,vlookup_table!$A:$G,3,FALSE) -> HI | P35: =VLOOKUP(A35,vlookup_table!$A:$G,4,FALSE) -> 2401 | Q35: =VLOOKUP(A35,vlookup_table!$A:$G,5,FALSE) -> C2 | R35: =VLOOKUP(A35,vlookup_table!$A:$G,6,FALSE) -> F | S35: =VLOOKUP(A35,vlookup_table!$A:$G,7,FALSE) -> 21 | T35: =97-LEFT(P35,2)-IF(RIGHT(P35,2)>6,1,0) -> 72 | U35: =IF(LEFT(Q35,1)="C","Ciudad",IF(LEFT(Q35,1)="T","Pueblo",IF(LEFT(Q35,1)="R","Rural",IF(LEFT(Q35,1)="S","Suburbano",IF(LEFT(Q35,1)="U","Urbano",""))))) -> Ciudad
A36: 11011 | B36: FL | C36: M | D36: 559 | E36: 232 | F36: 269 | G36: 0 | H36: 10511 | I36: 11 | J36: 20 | K36: 270 | L36: 257 | M36: 12.611111 | N36: =VLOOKUP(A36,vlookup_table!$A:$G,2,FALSE) -> 1002 | O36: =VLOOKUP(A36,vlookup_table!$A:$G,3,FALSE) -> FL | P36: =VLOOKUP(A36,vlookup_table!$A:$G,4,FALSE) -> 2601 | Q36: =VLOOKUP(A36,vlookup_table!$A:$G,5,FALSE) -> S3 | R36: =VLOOKUP(A36,vlookup_table!$A:$G,6,FALSE) -> M | S36: =VLOOKUP(A36,vlookup_table!$A:$G,7,FALSE) -> 20 | T36: =97-LEFT(P36,2)-IF(RIGHT(P36,2)>6,1,0) -> 70 | U36: =IF(LEFT(Q36,1)="C","Ciudad",IF(LEFT(Q36,1)="T","Pueblo",IF(LEFT(Q36,1)="R","Rural",IF(LEFT(Q36,1)="S","Suburbano",IF(LEFT(Q36,1)="U","Urbano",""))))) -> Suburbano
A37: 116894 | B37: TX | C37: M | E37: 368 | F37: 531 | G37: 5 | H37: 33797 | I37: 2 | J37: 42 | K37: 457 | L37: 450 | M37: 12.25 | N37: =VLOOKUP(A37,vlookup_table!$A:$G,2,FALSE) -> 1 | O37: =VLOOKUP(A37,vlookup_table!$A:$G,3,FALSE) -> TX | P37: =VLOOKUP(A37,vlookup_table!$A:$G,4,FALSE) -> 2201 | Q37: =VLOOKUP(A37,vlookup_table!$A:$G,5,FALSE) -> U1 | R37: =VLOOKUP(A37,vlookup_table!$A:$G,6,FALSE) -> M | S37: =VLOOKUP(A37,vlookup_table!$A:$G,7,FALSE) -> 20 | T37: =97-LEFT(P37,2)-IF(RIGHT(P37,2)>6,1,0) -> 74 | U37: =IF(LEFT(Q37,1)="C","Ciudad",IF(LEFT(Q37,1)="T","Pueblo",IF(LEFT(Q37,1)="R","Rural",IF(LEFT(Q37,1)="S","Suburbano",IF(LEFT(Q37,1)="U","Urbano",""))))) -> Urbano
A38: 154245 | B38: CA | C38: F | D38: 596 | E38: 164 | F38: 190 | G38: 0 | H38: 5273 | I38: 23 | J38: 57 | K38: 168 | L38: 181 | M38: 16.5 | N38: =VLOOKUP(A38,vlookup_table!$A:$G,2,FALSE) -> 2 | O38: =VLOOKUP(A38,vlookup_table!$A:$G,3,FALSE) -> CA | P38: =VLOOKUP(A38,vlookup_table!$A:$G,4,FALSE) -> 4304 | Q38: =VLOOKUP(A38,vlookup_table!$A:$G,5,FALSE) -> R1 | R38: =VLOOKUP(A38,vlookup_table!$A:$G,6,FALSE) -> F | S38: =VLOOKUP(A38,vlookup_table!$A:$G,7,FALSE) -> 15 | T38: =97-LEFT(P38,2)-IF(RIGHT(P38,2)>6,1,0) -> 53 | U38: =IF(LEFT(Q38,1)="C","Ciudad",IF(LEFT(Q38,1)="T","Pueblo",IF(LEFT(Q38,1)="R","Rural",IF(LEFT(Q38,1)="S","Suburbano",IF(LEFT(Q38,1)="U","Urbano",""))))) -> Rural
A39: 134773 | B39: UT | C39: M | D39: 706 | E39: 362 | F39: 394 | G39: 1 | H39: 10420 | I39: 1 | J39: 82 | K39: 376 | L39: 379 | M39: 15 | N39: =VLOOKUP(A39,vlookup_table!$A:$G,2,FALSE) -> 1 | O39: =VLOOKUP(A39,vlookup_table!$A:$G,3,FALSE) -> UT | P39: =VLOOKUP(A39,vlookup_table!$A:$G,4,FALSE) -> 3201 | Q39: =VLOOKUP(A39,vlookup_table!$A:$G,5,FALSE) -> C3 | R39: =VLOOKUP(A39,vlookup_table!$A:$G,6,FALSE) -> M | S39: =VLOOKUP(A39,vlookup_table!$A:$G,7,FALSE) -> 25 | T39: =97-LEFT(P39,2)-IF(RIGHT(P39,2)>6,1,0) -> 64 | U39: =IF(LEFT(Q39,1)="C","Ciudad",IF(LEFT(Q39,1)="T","Pueblo",IF(LEFT(Q39,1)="R","Rural",IF(LEFT(Q39,1)="S","Suburbano",IF(LEFT(Q39,1)="U","Urbano",""))))) -> Ciudad
A40: 26271 | B40: GA | C40: F | D40: 878 | E40: 310 | F40: 588 | G40: 30 | H40: 22281 | I40: 4 | J40: 55 | K40: 517 | L40: 433 | M40: 10.133333 | N40: =VLOOKUP(A40,vlookup_table!$A:$G,2,FALSE) -> 28 | O40: =VLOOKUP(A40,vlookup_table!$A:$G,3,FALSE) -> GA | P40: =VLOOKUP(A40,vlookup_table!$A:$G,4,FALSE) -> 3701 | Q40: =VLOOKUP(A40,vlookup_table!$A:$G,5,FALSE) -> C2 | R40: =VLOOKUP(A40,vlookup_table!$A:$G,6,FALSE) -> F | S40: =VLOOKUP(A40,vlookup_table!$A:$G,7,FALSE) -> 16 | T40: =97-LEFT(P40,2)-IF(RIGHT(P40,2)>6,1,0) -> 59 | U40: =IF(LEFT(Q40,1)="C","Ciudad",IF(LEFT(Q40,1)="T","Pueblo",IF(LEFT(Q40,1)="R","Rural",IF(LEFT(Q40,1)="S","Suburbano",IF(LEFT(Q40,1)="U","Urbano",""))))) -> Ciudad
...

Sheet vlookup_table
A1: CONTROLN | B1: TCODE | C1: STATE | D1: DOB | E1: DOMAIN | F1: GENDER | G1: TARGET_D
A2: 44060 | B2: 1 | C2: FL | D2: 1901 | E2: C2 | F2: M | G2: 100
A3: 96093 | B3: 0 | C3: IL | D3: 0 | E3: T2 | F3: M | G3: 7
A4: 43333 | B4: 0 | C4: FL | D4: 2501 | E4: C2 | F4: F | G4: 5
A5: 21885 | B5: 0 | C5: NC | D5: 2208 | E5: T2 | F5: M | G5: 38
A6: 190108 | B6: 28 | C6: FL | D6: 0 | E6: C2 | F6: F | G6: 5
A7: 100640 | B7: 1 | C7: IL | D7: 6104 | E7: S2 | F7: M | G7: 30
A8: 18581 | B8: 0 | C8: NC | D8: 4407 | E8: R2 | F8: F | G8: 12
A9: 119038 | B9: 1002 | C9: TX | D9: 0 | E9: C1 | F9: M | G9: 7
A10: 173223 | B10: 0 | C10: CA | D10: 1801 | E10: T2 | F10: F | G10: 10
A11: 157988 | B11: 28 | C11: CA | D11: 0 | E11: S1 | F11: F | G11: 10
A12: 141720 | B12: 28 | C12: NV | D12: 5401 | E12: T1 | F12: F | G12: 5
A13: 186272 | B13: 2 | C13: CA | D13: 3401 | E13: U1 | F13: F | G13: 10
A14: 154301 | B14: 2 | C14: CA | D14: 2801 | E14: T2 | F14: F | G14: 10
A15: 189722 | B15: 1 | C15: AP | D15: 0 | F15: M | G15: 6
A16: 188304 | B16: 0 | C16: KS | D16: 2405 | E16: T2 | F16: F | G16: 10
A17: 73699 | B17: 1 | C17: MI | D17: 5102 | E17: S1 | G17: 15
A18: 31977 | B18: 2 | C18: FL | D18: 2701 | E18: T1 | F18: F | G18: 28
A19: 44336 | B19: 0 | C19: FL | D19: 6501 | E19: C2 | F19: F | G19: 15
A20: 127823 | B20: 2 | C20: TX | D20: 2301 | E20: C3 | F20: F | G20: 6
A21: 150739 | B21: 2 | C21: CA | D21: 5410 | E21: S1 | F21: U | G21: 12
A22: 41384 | B22: 28 | C22: FL | D22: 5107 | E22: S3 | F22: F | G22: 12
A23: 114721 | B23: 0 | C23: OK | D23: 0 | E23: C2 | G23: 15
A24: 111795 | B24: 0 | C24: AR | D24: 0 | G24: 5
A25: 64480 | B25: 28 | C25: IN | D25: 0 | E25: T2 | F25: F | G25: 10
A26: 87259 | B26: 2 | C26: MT | D26: 4304 | E26: C1 | F26: M | G26: 25
A27: 115823 | B27: 0 | C27: TX | D27: 0 | E27: S1 | F27: M | G27: 15
A28: 95701 | B28: 1 | C28: IL | D28: 4406 | E28: S2 | F28: M | G28: 5
A29: 5172 | B29: 1 | C29: IL | D29: 6105 | E29: R3 | F29: M | G29: 10
A30: 152486 | B30: 1 | C30: CA | D30: 2401 | E30: S2 | F30: M | G30: 5
A31: 153880 | B31: 2 | C31: WI | D31: 5001 | E31: S1 | F31: F | G31: 5
A32: 101855 | B32: 1 | C32: MO | D32: 2401 | E32: C2 | F32: M | G32: 10
A33: 62932 | B33: 1 | C33: IN | D33: 0 | E33: S3 | F33: M | G33: 10
A34: 125930 | B34: 0 | C34: TX | D34: 4806 | E34: R2 | F34: F | G34: 75
A35: 173653 | B35: 28 | C35: HI | D35: 2401 | E35: C2 | F35: F | G35: 21
A36: 11011 | B36: 1002 | C36: FL | D36: 2601 | E36: S3 | F36: M | G36: 20
... A43: 133806 | B43: 0 | C43: ID | D43: 0 | E43: T2 | F43: U | G43: 15
A44: 112632 | B44: 2 | C44: CT | D44: 5001 | F44: M | G44: 11
A45: 143253 | B45: 0 | C45: CA | D45: 2101 | E45: U3 | F45: F | G45: 5
A46: 403 | B46: 0 | C46: AL | D46: 3901 | F46: J | G46: 35
...
